2022-10-10 16:58:38,510 ERROR frappe Could not take error snapshot: name 'six' is not defined
Site: abakada-assessment.com
Form Dict: {}
Traceback (most recent call last):
  File "/home/jopet2/frappe-bench/apps/frappe/frappe/app.py", line 55, in application
    init_request(request)
  File "/home/jopet2/frappe-bench/apps/frappe/frappe/app.py", line 130, in init_request
    frappe.local.http_request = frappe.auth.HTTPRequest()
  File "/home/jopet2/frappe-bench/apps/frappe/frappe/auth.py", line 37, in __init__
    self.set_session()
  File "/home/jopet2/frappe-bench/apps/frappe/frappe/auth.py", line 74, in set_session
    frappe.local.login_manager = LoginManager()
  File "/home/jopet2/frappe-bench/apps/frappe/frappe/auth.py", line 130, in __init__
    self.make_session(resume=True)
  File "/home/jopet2/frappe-bench/apps/frappe/frappe/auth.py", line 216, in make_session
    frappe.local.session_obj = Session(
  File "/home/jopet2/frappe-bench/apps/frappe/frappe/sessions.py", line 215, in __init__
    self.resume()
  File "/home/jopet2/frappe-bench/apps/frappe/frappe/sessions.py", line 282, in resume
    data = self.get_session_record()
  File "/home/jopet2/frappe-bench/apps/frappe/frappe/sessions.py", line 300, in get_session_record
    r = self.get_session_data()
  File "/home/jopet2/frappe-bench/apps/frappe/frappe/sessions.py", line 316, in get_session_data
    data = self.get_session_data_from_db()
  File "/home/jopet2/frappe-bench/apps/frappe/frappe/sessions.py", line 338, in get_session_data_from_db
    self.device = frappe.db.sql("SELECT `device` FROM `tabSessions` WHERE `sid`=%s", self.sid)
  File "/home/jopet2/frappe-bench/apps/frappe/frappe/database/database.py", line 148, in sql
    self.connect()
  File "/home/jopet2/frappe-bench/apps/frappe/frappe/database/database.py", line 84, in connect
    self._conn = self.get_connection()
  File "/home/jopet2/frappe-bench/apps/frappe/frappe/database/mariadb/database.py", line 76, in get_connection
    conn = pymysql.connect(
  File "/home/jopet2/frappe-bench/env/lib/python3.8/site-packages/pymysql/connections.py", line 353, in __init__
    self.connect()
  File "/home/jopet2/frappe-bench/env/lib/python3.8/site-packages/pymysql/connections.py", line 633, in connect
    self._request_authentication()
  File "/home/jopet2/frappe-bench/env/lib/python3.8/site-packages/pymysql/connections.py", line 907, in _request_authentication
    auth_packet = self._read_packet()
  File "/home/jopet2/frappe-bench/env/lib/python3.8/site-packages/pymysql/connections.py", line 725, in _read_packet
    packet.raise_for_error()
  File "/home/jopet2/frappe-bench/env/lib/python3.8/site-packages/pymysql/protocol.py", line 221, in raise_for_error
    err.raise_mysql_exception(self._data)
  File "/home/jopet2/frappe-bench/env/lib/python3.8/site-packages/pymysql/err.py", line 143, in raise_mysql_exception
    raise errorclass(errno, errval)
pymysql.err.OperationalError: (1045, "Access denied for user '_51f9a5b86fef33d2'@'localhost' (using password: YES)")

During handling of the above exception, another exception occurred:

Traceback (most recent call last):
  File "/home/jopet2/frappe-bench/apps/frappe/frappe/utils/error.py", line 49, in make_error_snapshot
    snapshot = get_snapshot(exception)
  File "/home/jopet2/frappe-bench/apps/frappe/frappe/utils/error.py", line 66, in get_snapshot
    if isinstance(etype, six.class_types):
NameError: name 'six' is not defined
